Workbook
Name Slicer_Representative: #N/A

Sheet dahsboard
C1: Call Center Report-2023
O15: =pivot_data!B87 -> R01 | P15: =pivot_data!C87 -> R02 | Q15: =pivot_data!D87 -> R03 | R15: =pivot_data!E87 -> R04 | S15: =pivot_data!F87 -> R05 | T15: Total
N16: {=IF(pivot_data!A88:G105="","",pivot_data!A88:G105)} -> Cincinnati
N17: C0003 | O17: 891 | P17: 1332 | Q17: 1282 | R17: 739 | S17: 560 | T17: 4804
N18: C0004 | O18: 1991 | P18: 1886 | Q18: 1206 | R18: 884 | S18: 1722 | T18: 7689
N19: C0011 | O19: 1163 | P19: 1180 | Q19: 1616 | R19: 1043 | S19: 1747 | T19: 6749
N20: C0012 | O20: 1438 | P20: 1616 | Q20: 866 | R20: 829 | S20: 2070 | T20: 6819
N21: Cleveland
N22: C0002 | O22: 1233 | P22: 223 | Q22: 1680 | R22: 990 | S22: 1508 | T22: 5634
N23: C0007 | O23: 1598 | P23: 1907 | Q23: 869 | R23: 1426 | S23: 1416 | T23: 7216
N24: C0008 | O24: 900 | P24: 1016 | Q24: 960 | R24: 940 | S24: 1193 | T24: 5009
N25: C0010 | O25: 900 | P25: 1470 | Q25: 1617 | R25: 1314 | S25: 941 | T25: 6242
N26: C0013 | O26: 1255 | P26: 516 | Q26: 1874 | R26: 1863 | S26: 1722 | T26: 7230
N27: C0015 | O27: 1138 | P27: 1898 | Q27: 1482 | R27: 846 | S27: 1154 | T27: 6518
N28: Columbus
N29: C0001 | O29: 1655 | P29: 805 | Q29: 2263 | R29: 987 | S29: 1075 | T29: 6785
N30: C0005 | O30: 1104 | P30: 2280 | Q30: 1445 | R30: 1722 | S30: 1196 | T30: 7747
N31: C0006 | O31: 372 | P31: 1818 | Q31: 1346 | R31: 1156 | S31: 1484 | T31: 6176
N32: C0009 | O32: 1415 | P32: 1271 | Q32: 1214 | R32: 1135 | S32: 1566 | T32: 6601
N33: C0014 | O33: 1362 | P33: 1363 | Q33: 1152 | R33: 777 | S33: 750 | T33: 5404

Sheet pivot_data
A3: Count Calls | B3: Total Amount | C3: Total Duration | D3: Avg Rating | E3: 5* rating
A4: 1000 | B4: 96623 | C4: 89850 | D4: 3.8854 | E4: 307
A11: Count Calls | B11: Total Amount | C11: Total Duration | D11: Avg Rating | E11: 5* rating
A12: 200 | B12: 20104 | C12: 18209 | D12: 3.8825 | E12: 51
A17: Row Labels | B17: Count Calls | C17: Count Calls2
A18: Jan | B18: 21 | C18: 21
A19: Feb | B19: 18 | C19: 18 | M19: Row Labels | N19: Count Calls
A20: Mar | B20: 31 | C20: 31 | M20: Sunday | N20: 27
A21: Apr | B21: 20 | C21: 20 | M21: Monday | N21: 22
A22: May | B22: 8 | C22: 8 | M22: Tuesday | N22: 27
A23: Jun | B23: 12 | C23: 12 | M23: Wednesday | N23: 27
A24: Jul | B24: 12 | C24: 12 | M24: Thursday | N24: 27
A25: Aug | B25: 7 | C25: 7 | M25: Friday | N25: 32
A26: Sep | B26: 20 | C26: 20 | M26: Saturday | N26: 38
A27: Oct | B27: 24 | C27: 24 | M27: Grand Total | N27: 200
A28: Nov | B28: 12 | C28: 12
A29: Dec | B29: 15 | C29: 15
A30: Grand Total | B30: 200 | C30: 200
F35: reprenstative: | G35: =A54 -> R05
F39: for graph
A40: Row Labels | B40: Count Calls | C40: Total Amount
A41: R01 | B41: 189 | C41: 18415 | F41: rep | G41: calls | H41: amount | I41: sel.calls | J41: sel.amount
A42: R02 | B42: 218 | C42: 20581 | F42: R01 | G42: 189 | H42: =C41 -> 18415 | I42: =IF(F42=$G$35,G42,"NA()") -> NA() | J42: =IF(F42=$G$35,H42,"NA()") -> NA()
A43: R03 | B43: 207 | C43: 20872 | F43: R02 | G43: 218 | H43: =C42 -> 20581 | I43: =IF(F43=$G$35,G43,"NA()") -> NA() | J43: =IF(F43=$G$35,H43,"NA()") -> NA()
A44: R04 | B44: 186 | C44: 16651 | F44: R03 | G44: 207 | H44: =C43 -> 20872 | I44: =IF(F44=$G$35,G44,"NA()") -> NA() | J44: =IF(F44=$G$35,H44,"NA()") -> NA()
A45: R05 | B45: 200 | C45: 20104 | F45: R04 | G45: 186 | H45: =C44 -> 16651 | I45: =IF(F45=$G$35,G45,"NA()") -> NA() | J45: =IF(F45=$G$35,H45,"NA()") -> NA()
A46: Grand Total | B46: 1000 | C46: 96623 | F46: R05 | G46: 200 | H46: =C45 -> 20104 | I46: =IF(F46=$G$35,G46,"NA()") -> 200 | J46: =IF(F46=$G$35,H46,"NA()") -> 20104
A53: Row Labels
A54: R05
A55: Grand Total
A63: Count Calls | B63: Column Labels
A64: Row Labels | B64: Female | C64: Male | D64: Grand Total
A65: Cincinnati | B65: 144 | C65: 132 | D65: 276
A66: Cleveland | B66: 326 | C66: 63 | D66: 389
A67: Columbus | B67: 129 | C67: 206 | D67: 335
A68: Grand Total | B68: 599 | C68: 401 | D68: 1000
A73: Row Labels | B73: Count Calls | H73: Rating List
A74: 0 | H74: 0
A75: 1 | H75: 1
A76: 2 | B76: 10 | H76: 2
...
